{
  "comments": [
    {
      "key": {
        "uuid": "c01a3a0e_bc8a7ad4",
        "filename": "gclient_utils.py",
        "patchSetId": 11
      },
      "lineNbr": 593,
      "author": {
        "id": 1003232
      },
      "writtenOn": "2020-08-21T21:52:55Z",
      "side": 1,
      "message": "I don\u0027t think this\u0027ll work on windows (hence your tryjob failure).",
      "revId": "1794ec8f7ee5c0edbe0f392c026c41fc9ccb4725",
      "serverId": "3ce6091f-6c88-37e8-8c75-72f92ae8dfba",
      "unresolved": true
    },
    {
      "key": {
        "uuid": "1bd370e6_d663127f",
        "filename": "gclient_utils.py",
        "patchSetId": 11
      },
      "lineNbr": 626,
      "author": {
        "id": 1170419
      },
      "writtenOn": "2020-08-21T19:06:36Z",
      "side": 1,
      "message": "It\u0027s weird, but the err gets thrown for every subproc. Not sure how or why... ?",
      "revId": "1794ec8f7ee5c0edbe0f392c026c41fc9ccb4725",
      "serverId": "3ce6091f-6c88-37e8-8c75-72f92ae8dfba",
      "unresolved": true
    },
    {
      "key": {
        "uuid": "ca41e1b6_34894e02",
        "filename": "gclient_utils.py",
        "patchSetId": 11
      },
      "lineNbr": 626,
      "author": {
        "id": 1003232
      },
      "writtenOn": "2020-08-21T21:51:43Z",
      "side": 1,
      "message": "EIO likely means you tried to read on a closed fd.",
      "parentUuid": "1bd370e6_d663127f",
      "revId": "1794ec8f7ee5c0edbe0f392c026c41fc9ccb4725",
      "serverId": "3ce6091f-6c88-37e8-8c75-72f92ae8dfba",
      "unresolved": true
    }
  ]
}