{
  "comments": [
    {
      "unresolved": false,
      "key": {
        "uuid": "e74f5bd5_8f4a1572",
        "filename": "/PATCHSET_LEVEL",
        "patchSetId": 2
      },
      "lineNbr": 0,
      "author": {
        "id": 1003232
      },
      "writtenOn": "2021-05-19T22:31:23Z",
      "side": 1,
      "message": "ehmaldonado, please take another look?",
      "revId": "48c2b9f268f960116b4ba4531cf7cb20b62d7e70",
      "serverId": "3ce6091f-6c88-37e8-8c75-72f92ae8dfba"
    },
    {
      "unresolved": false,
      "key": {
        "uuid": "a22d3b81_43dacd15",
        "filename": "/PATCHSET_LEVEL",
        "patchSetId": 2
      },
      "lineNbr": 0,
      "author": {
        "id": 1340678
      },
      "writtenOn": "2021-05-19T22:55:51Z",
      "side": 1,
      "message": "I cherry-picked this into my depot_tools.  Python2 still passes, and Python3 complains with the following:\n\n\u003e git cl presubmit -u\nRunning Python 2 presubmit upload checks ...\nDone processing C:\\src\\chromium-ooppd\\src\\chrome\\browser\\printing\\print_backend_service_manager.cc\n\nPresubmit checks took 44.0s to calculate.\n\nPython 2 presubmit checks passed.\nRunning Python 3 presubmit upload checks ...\nTraceback (most recent call last):\n  File \"C:\\src\\depot_tools\\presubmit_support.py\", line 1661, in _run_check_function\n    result \u003d eval(function_name + \u0027(*__args)\u0027, context)\n  File \"\u003cstring\u003e\", line 1, in \u003cmodule\u003e\n  File \"PRESUBMIT.py\", line 4254, in ChecksCommon\n    input_api.canned_checks.CheckAuthorizedAuthor(input_api, output_api))\n  File \"C:\\src\\depot_tools\\presubmit_canned_checks.py\", line 135, in CheckAuthorizedAuthor\n    valid_authors.append(m.group(1)).lower()\nAttributeError: \u0027NoneType\u0027 object has no attribute \u0027lower\u0027\n\nDuring handling of the above exception, another exception occurred:\n\nTraceback (most recent call last):\n  File \"C:\\src\\depot_tools\\presubmit_support.py\", line 2041, in \u003cmodule\u003e\n    sys.exit(main())\n  File \"C:\\src\\depot_tools\\presubmit_support.py\", line 2022, in main\n    return DoPresubmitChecks(\n  File \"C:\\src\\depot_tools\\presubmit_support.py\", line 1760, in DoPresubmitChecks\n    results +\u003d executer.ExecPresubmitScript(presubmit_script, filename)\n  File \"C:\\src\\depot_tools\\presubmit_support.py\", line 1622, in ExecPresubmitScript\n    self._run_check_function(function_name, context, sink))\n  File \"C:\\src\\depot_tools\\presubmit_support.py\", line 1670, in _run_check_function\n    six.reraise(e_type, \u0027Evaluation of %s failed: %s\u0027 % (function_name,\n  File \"C:\\Users\\awscreen\\.vpython-root\\908550\\lib\\site-packages\\six.py\", line 684, in reraise\n    if value.__traceback__ is not tb:\nAttributeError: \u0027str\u0027 object has no attribute \u0027__traceback__\u0027\n+\u003d\u003d\u003d\u003d\u003d\u003d\u003d\u003d\u003d\u003d\u003d\u003d\u003d\u003d\u003d\u003d\u003d\u003d\u003d\u003d\u003d\u003d\u003d\u003d\u003d\u003d\u003d\u003d\u003d\u003d\u003d\u003d\u003d\u003d\u003d\u003d\u003d\u003d\u003d\u003d\u003d\u003d\u003d\u003d\u003d\u003d\u003d\u003d\u003d\u003d\u003d+\n|      METRICS COLLECTION IS TAKING PLACE           |\n|                                                   |\n| To suppress this message opt in or out using:     |\n| $ gclient metrics [--opt-in] [--opt-out]          |\n| For more information please see metrics.README.md |\n| in your depot_tools checkout or visit             |\n| https://goo.gl/yNpRDV.                            |\n+\u003d\u003d\u003d\u003d\u003d\u003d\u003d\u003d\u003d\u003d\u003d\u003d\u003d\u003d\u003d\u003d\u003d\u003d\u003d\u003d\u003d\u003d\u003d\u003d\u003d\u003d\u003d\u003d\u003d\u003d\u003d\u003d\u003d\u003d\u003d\u003d\u003d\u003d\u003d\u003d\u003d\u003d\u003d\u003d\u003d\u003d\u003d\u003d\u003d\u003d\u003d+",
      "parentUuid": "e74f5bd5_8f4a1572",
      "revId": "48c2b9f268f960116b4ba4531cf7cb20b62d7e70",
      "serverId": "3ce6091f-6c88-37e8-8c75-72f92ae8dfba"
    }
  ]
}