{
  "comments": [
    {
      "key": {
        "uuid": "705120f4_b35782e6",
        "filename": "git_cl.py",
        "patchSetId": 1
      },
      "lineNbr": 4525,
      "author": {
        "id": 1115956
      },
      "writtenOn": "2016-11-28T13:24:02Z",
      "side": 1,
      "message": "What if somebody with a screwed up local clock tries to commit something that\u0027s in a far away future?",
      "range": {
        "startLine": 4525,
        "startChar": 10,
        "endLine": 4525,
        "endChar": 57
      },
      "revId": "54450d7e25972ca976bbe03eac36ef63d347bda2",
      "serverId": "3ce6091f-6c88-37e8-8c75-72f92ae8dfba",
      "unresolved": false
    },
    {
      "key": {
        "uuid": "5056dcee_1584b45c",
        "filename": "git_cl.py",
        "patchSetId": 1
      },
      "lineNbr": 4525,
      "author": {
        "id": 1141499
      },
      "writtenOn": "2016-11-29T14:46:00Z",
      "side": 1,
      "message": "well, the comment is still correct :) But yes, that\u0027s a hard problem -\u003e see go/git-numberer. It has been the problem before with gnumbd, as it used the same algo,  and I don\u0027t see good reason to solve it now.",
      "parentUuid": "705120f4_b35782e6",
      "revId": "54450d7e25972ca976bbe03eac36ef63d347bda2",
      "serverId": "3ce6091f-6c88-37e8-8c75-72f92ae8dfba",
      "unresolved": false
    },
    {
      "key": {
        "uuid": "b04b9845_b5004a1e",
        "filename": "tests/git_cl_test.py",
        "patchSetId": 1
      },
      "lineNbr": 1027,
      "author": {
        "id": 1153089
      },
      "writtenOn": "2016-11-28T12:16:08Z",
      "side": 1,
      "message": "Why is this necesary? The default value is already False.",
      "range": {
        "startLine": 1027,
        "startChar": 31,
        "endLine": 1027,
        "endChar": 49
      },
      "revId": "54450d7e25972ca976bbe03eac36ef63d347bda2",
      "serverId": "3ce6091f-6c88-37e8-8c75-72f92ae8dfba",
      "unresolved": false
    },
    {
      "key": {
        "uuid": "303fa899_91799e73",
        "filename": "tests/git_cl_test.py",
        "patchSetId": 1
      },
      "lineNbr": 1027,
      "author": {
        "id": 1141499
      },
      "writtenOn": "2016-11-28T12:21:44Z",
      "side": 1,
      "message": "more as a note to self if the test fails. This is because there is try: finally: inside CMDLand,  which means that if test fails somewhere inside try: block, the actual error thrown will be from finally catch not matching expectations :(",
      "parentUuid": "b04b9845_b5004a1e",
      "revId": "54450d7e25972ca976bbe03eac36ef63d347bda2",
      "serverId": "3ce6091f-6c88-37e8-8c75-72f92ae8dfba",
      "unresolved": false
    }
  ]
}