{
  "comments": [
    {
      "key": {
        "uuid": "ce432c34_a6d4b719",
        "filename": "/COMMIT_MSG",
        "patchSetId": 3
      },
      "lineNbr": 12,
      "author": {
        "id": 1141499
      },
      "writtenOn": "2017-11-23T02:24:14Z",
      "side": 1,
      "message": "unfortunately, i have no idea what\u0027s the root cause for that error,\nbut this change, I think, is good regardless of python deployment woes.",
      "range": {
        "startLine": 8,
        "startChar": 0,
        "endLine": 12,
        "endChar": 67
      },
      "revId": "b9d77a6365721e79909773ba31a28237c3330535",
      "serverId": "3ce6091f-6c88-37e8-8c75-72f92ae8dfba",
      "unresolved": true
    }
  ]
}